Workbook
Name basevendeurs: #REF!
Name basevendeurs: #REF!
Name basevendeurs: #REF!
Name basevendeurs: #REF!
Name basevendeurs: #REF!
Name basevendeurs: #REF!
Name basevendeurs: #REF!
Name basevendeurs: #REF!
Name basevendeurs: #REF!
Name basevendeurs: #REF!
Name basevendeurs: #REF!
Name basevendeurs: #REF!
Name CD: #REF!
Name CD: #REF!
Name CD: #REF!
Name CD: #REF!
Name CD: #REF!
Name CD: #REF!
Name CD: #REF!
Name CD: #REF!
Name CD: #REF!
Name CD: #REF!
Name CD: #REF!
Name CD: #REF!
Name ChronologieNative_Date_de_Facturation: #N/A
Name ChronologieNative_Date_de_Facturation1: #N/A
Name ChronologieNative_Date_de_Facturation12: #N/A
Name ChronologieNative_Date_de_Facturation121: #N/A
Name ChronologieNative_Date_de_Facturation1211: #N/A
Name ChronologieNative_Date_de_Facturation1221: #N/A
Name ChronologieNative_Date_de_Facturation12211: #N/A
Name ChronologieNative_Date_de_Facturation122111: #N/A
Name ChronologieNative_Date_de_Facturation12212: #N/A
Name ChronologieNative_Date_de_Facturation122121: #N/A
Name ChronologieNative_Date_de_Facturation1221211: #N/A
Name ChronologieNative_Date_de_Facturation2: #N/A
Name LSPBL: #REF!
Name LSPBL: #REF!
Name LSPBL: #REF!
Name LSPBL: #REF!
Name LSPBL: #REF!
Name LSPBL: #REF!
Name LSPBL: #REF!
Name LSPBL: #REF!
Name LSPBL: #REF!
Name LSPBL: #REF!
Name LSPBL: #REF!
Name LSPBL: #REF!
Name nbredemois: #REF!
Name Segment_Equipe: #N/A
Name Segment_Equipe1: #N/A
Name Segment_Etat: #N/A
Name Segment_Etat1: #N/A
Name Segment_Etat11: #N/A
Name Segment_Etat111: #N/A
Name Segment_Etat12: #N/A
Name Segment_Etat121: #N/A
Name Segment_Etat1211: #N/A
Name Segment_Marge_négative: #N/A
Name Segment_Marge_nette: #N/A

Sheet Suppression CD
A1: Site | B1: Etat | C1: Marque | D1: Date de Facturation | E1: Date de Livraison | F1: Manque Marge | G1: PB Marge | H1: Justif ? | I1: Solde Client | J1: Validé DF | K1: Solde client2 | L1: Vendeur | M1: N° VN | N1: N° CDE | O1: Châssis | P1: CLIENT | Q1: Marge nette | R1: Marge restante | S1: % PV | T1: OP Clos | U1: OP Ouverts | V1: OP non visible | W1: libellé OP non visible | X1: TX COM | Y1: TX COM Opticar | Z1: Commission de Base | AA1: Prime opération | AB1: Total COM | AC1: Sté de Financement | AD1: EXT GIE | AE1: Forfait immat | AF1: nbre de forfait | AG1: nbre de livraison | AH1: OP "+ / -" | AI1: date | AJ1: % forfait | AK1: Site3 | AL1: Marque4 | AM1: non utilisé | AN1: Equipe | AO1: Marge nette recalculée | AP1: % PV5 | AQ1: Marge négativr

Sheet Base Vendeurs
A1: aaa
A2: ADTDE | B2: Val de Lys
A3: ARKDE | B3: Valauto Arras
A4: ARLFO | B4: Valauto Arras
A5: ARLKO | B5: Valauto Arras
A6: ARLPA | B6: Valauto Arras
A7: ARMPO | B7: Valauto Arras
A8: ARPDE | B8: Valauto Arras
A9: ARRDE | B9: Valauto Arras
A10: ARTRE | B10: Valauto Arras
A11: ARXPAD | B11: Valauto Arras
A12: ASACH | B12: Val de Lys
A13: ASCDI | B13: Val de Lys
... A221: VATDR | B221: Valauto Hainaut AUDI

Sheet Base Sites
A2: 60 | B2: Val de Lys Automobiles
A3: 30 | B3: Valauto Lambersart VW
A4: 10 | B4: Valauto Roncq
A5: 80 | B5: Valauto Artois
A6: NI | B6: Valauto Béthune
A7: 30 | B7: Valauto Lomme (avant le 01/07/19)
A8: 70 | B8: Valauto Lomme
A9: 30 | B9: Valauto Lambersart Sk
A10: 20 | B10: Valauto Professionnels
A11: 15 | B11: Valauto Hainaut
A12: 25 | B12: Valauto Maubeuge
A13: 35 | B13: Valauto Cambrai
A14: 45 | B14: Valauto Arras

Sheet Marges_Marques N 5
A1: VALAUTO - Analyse des Marges VN / MARQUE
B7: Nbre de LIV. | C7: PV MOYEN Hors Transport | D7: Moyenne de Total COM | E7: Marge nette moyenne
A8: Total général

Sheet Marges_Vendeurs N 7
A1: VALAUTO - Marges VN / Vendeurs
A3: =+'Marges_Marques N 5'!A3 -> 0
A5: Marque | B5: VW
B7: Nbre de LIV. | C7: PV MOYEN Hors Transport | D7: Marge nette moyenne | E7: Moyenne de Total COM
A8: ASCDI | B8: 1 | C8: 45183.33 | D8: 1405.52 | E8: 131.052
A9: LTHVI | B9: 1 | C9: 40900.84 | D9: 2927.69 | E9: 245.4348
A10: LTMEL | B10: 9 | C10: 41121.347 | D10: 103.51778 | E10: 0
A11: RQCSA | B11: 8 | C11: 25496.534 | D11: 1242.475 | E11: 153.90894
A12: RQFST | B12: 1 | C12: 42741.67 | D12: 949.85 | E12: 85.485
A13: RQHWI | B13: 6 | C13: 36682.702 | D13: 1727.55 | E13: 130.54873
A14: RQNBA | B14: 2 | C14: 27382.075 | D14: 1025.635 | E14: 67.65405
A15: RQSVA | B15: 3 | C15: 37284.75 | D15: 1459.6233 | E15: 221.05043
A16: RXNTA | B16: 14 | C16: 36730.361 | D16: 1700.0036 | E16: 153.7475
A17: VSGNI | B17: 9 | C17: 36496.627 | D17: 1122.2133 | E17: 106.89453
A18: VSYPA | B18: 8 | C18: 34190.285 | D18: 687.3975 | E18: 62.98895
A19: VSGLE | B19: 1 | C19: 39350 | D19: 457.84 | E19: 36.284
A20: 0 | B20: 1 | C20: 40146.96 | D20: 0 | E20: 0
A21: RQBER | B21: 4 | C21: 30207.215 | D21: -1241.245 | E21: 0
A22: VSFCA | B22: 7 | C22: 34114.203 | D22: 719.13429 | E22: 82.411143
A23: RQLGU | B23: 4 | C23: 42431.732 | D23: 3416.0575 | E23: 364.01135
A24: VSRPO | B24: 1 | C24: 45503.3 | D24: 3569.28 | E24: 275.0556
A25: LTBCL | B25: 6 | C25: 27840.755 | D25: 1549.4533 | E25: 187.06878
A26: LTTDU | B26: 1 | C26: 44902.49 | D26: -4671.67 | E26: 0
A27: LTNFA | B27: 5 | C27: 35279.022 | D27: 1151.206 | E27: 114.18822
A28: LTSVA | B28: 1 | C28: 30581.27 | D28: 1513.03 | E28: 141.803
A29: LTJEL | B29: 1 | C29: 31503.32 | D29: 2497.16 | E29: 192.1728
A30: ASTDU | B30: 2 | C30: 26770.42 | D30: 1490.585 | E30: 118.7137
A31: ASYPA | B31: 6 | C31: 34652.13 | D31: 1527.61 | E31: 169.04035
A32: ASMCO | B32: 2 | C32: 18910.545 | D32: 625.75 | E32: 42.46
A33: Total général | B33: 104 | C33: 34710.372 | D33: 1133.6444 | E33: 121.16927
A49: Marque | B49: (Plusieurs éléments)
B51: Nbre de LIV. | C51: PV MOYEN Hors Transport | D51: Marge nette moyenne | E51: Moyenne de Total COM
A52: Total général
A75: Marque | B75: (Plusieurs éléments)
B77: Nbre de LIV. | C77: PV MOYEN Hors Transport | D77: Marge nette moyenne | E77: Moyenne de Total COM
A78: Total général
A97: Marque | B97: (Plusieurs éléments)
B99: Nbre de LIV. | C99: PV MOYEN Hors Transport | D99: Marge nette moyenne | E99: Moyenne de Total COM
A100: Total général
A116: Marque | B116: (Plusieurs éléments)
...

Sheet Marges_Sites N 6
A1: VALAUTO - Marges VN / Vendeurs
O4: …..
B7: Nbre de LIV. | C7: Somme de Total | D7: Somme de Marge nette | E7: Moyenne de Marge nette recalculée2
A8: VW | B8: 11 | C8: 344458.04 | D8: 14803.85 | E8: 1345.8045
A9: ASYPA | B9: 6 | C9: 207912.78 | D9: 9165.66 | E9: 1527.61
A10: 60 | B10: 6 | C10: 207912.78 | D10: 9165.66 | E10: 1527.61
A11: ASTDU | B11: 2 | C11: 53540.84 | D11: 2981.17 | E11: 1490.585
A12: 30 | B12: 1 | C12: 22665 | D12: 935.91 | E12: 935.91
A13: 60 | B13: 1 | C13: 30875.84 | D13: 2045.26 | E13: 2045.26
A14: ASCDI | B14: 1 | C14: 45183.33 | D14: 1405.52 | E14: 1405.52
A15: ASMCO | B15: 2 | C15: 37821.09 | D15: 1251.5 | E15: 625.75
A16: 60 | B16: 2 | C16: 37821.09 | D16: 1251.5 | E16: 625.75
A17: Total général | B17: 11 | C17: 344458.04 | D17: 14803.85 | E17: 1345.8045

Sheet Marges VN recalculées
A1: Site | B1: 70
A2: Marque | B2: (Tous)
A4: Étiquettes de lignes | B4: Nombre de N° VN | C4: Somme de Marge nette recalculée | D4: Moyenne de Marge nette | E4: Moyenne de Marge nette recalculée
A5: I10 | B5: 5 | C5: 4184.19 | D5: 836.838 | E5: 836.838
A6: I20 | B6: 13 | C6: 13470.74 | D6: 1032.3646 | E6: 1036.2108
A7: I30 | B7: 3 | C7: 5178.87 | D7: 1726.29 | E7: 1726.29
A8: IONIQ | B8: 12 | C8: 18510.94 | D8: 1503.745 | E8: 1542.5783
A9: KONA | B9: 32 | C9: 55182.47 | D9: 1699.4522 | E9: 1724.4522
A10: SANTA FE | B10: 3 | C10: 7036.53 | D10: 2345.51 | E10: 2345.51
A11: TUCSON | B11: 13 | C11: 26501.81 | D11: 1996.2931 | E11: 2038.6008
A12: Total général | B12: 81 | C12: 130065.55 | D12: 1582.7105 | E12: 1605.7475

Sheet Marges VN
A1: Site | B1: Etat | C1: Marque | D1: Date de Facturation | E1: Date de Livraison | F1: Manque Marge | G1: PB Marge | H1: Justif ? | I1: Solde Client | J1: Validé DF | K1: Solde client2 | L1: Vendeur | M1: N° VN | N1: N° CDE | O1: Châssis | P1: CLIENT | Q1: Modèle livré | R1: Prix de Vte | S1: Options | T1: Total | U1: Jours de Stock | V1: Marge nette | W1: Marge s/transport | X1: déduction diverse | Y1: Marge restante | Z1: % PV | AA1: OP Clos | AB1: OP Ouverts | AC1: OP non visible | AD1: libellé OP non visible | AE1: TX COM | AF1: TX COM Opticar | AG1: Commission de Base | AH1: Prime opération | AI1: Total COM | AJ1: Sté de Financement | AK1: EXT GIE | AL1: Forfait immat | AM1: nbre de forfait | AN1: nbre de livraison | AO1: OP "+ / -" | AP1: date | AQ1: % forfait | AR1: AU | AS1: Marque4 | AT1: non utilisé | AU1: Equipe | AV1: Marge nette recalculée | AW1: % PV5 | AX1: Marge négative | AY1: TOTAL COM VENDEUR
A2: 60 | B2: C | C2: VW | D2: 46038 | E2: 46044 | K2: 0 | L2: RQCSA | M2: 89 | O2: WVGZZZE2XRP505667 | P2: DA COSTA LAETITIA | Q2: ID 5 | R2: 41363.33 | S2: 1433.33 | T2: =+R2+S2 -> 42796.66 | U2: 353 | V2: -4240.68 | W2: 95 | Y2: =+V2-W2+X2 -> -4335.68 | Z2: =(V2+X2)/T2 -> -0.099089041 | AA2: -2995.77 | AB2: 0 | AD2: marge négative // 1/2 cmm // Prise d'ordre le 08/01 et livraison le 22/01/2026 | AF2: 0.13 | AG2: =+Y2*AE2 -> 0 | AH2: 200 | AI2: =+AG2+AH2 -> 200 | AM2: =IF(AL2>0,100%,0%) -> 0 | AN2: =IF(A2>0,1,"") -> 1 | AQ2: =IF(AN2="","",+AM2/AN2) -> 0 | AR2: =IF(A2="","",VLOOKUP(A2,'Base Sites'!A:B,2,FALSE)) -> Val de Lys Automobiles | AS2: =IF(C2="VW","VOLKSWAGEN",IF(C2="SE","SEAT",IF(C2="NI","NISSAN",IF(C2="HY","HYUNDAI",IF(C2="VU","VUL",IF(C2="sk","SKODA",IF(C2="ltsk","SKODA",IF(C2="CUPRA","CUPRA",IF(C2="AUDI","AUDI",""))))))))) -> VOLKSWAGEN | AU2: =IF(A2="","",VLOOKUP(L2,'Base Vendeurs'!A:B,2,FALSE)) -> Valauto Roncq VW | AV2: =+V2+AO2 -> -4240.68 | AW2: =IF(A2="","",+AV2/T2) -> -0.099089041 | AX2: =IF(AV2<0,"OUI","NON") -> OUI | AY2: =+MargesVN[[#This Row],[Total COM]]+MargesVN[[#This Row],[EXT GIE]]+MargesVN[[#This Row],[Forfait immat]] -> 200
A3: 60 | B3: C | C3: VW | D3: 46052 | E3: 46046 | I3: x | J3: X | K3: -150 | L3: ASLME | M3: 94 | N3: 2705 | O3: WVGZZZCS8SY037022 | P3: POLET CLEMENT | Q3: TAIGO | R3: 24822.33 | S3: -145.84 | T3: =+R3+S3 -> 24676.49 | U3: 123 | V3: 380.41 | W3: 95 | Y3: =+V3-W3+X3 -> 285.41 | Z3: =(V3+X3)/T3 -> 0.015415888 | AA3: -2641.12 | AB3: 0 | AD3: ok vn payé / solde client acpte 2025 non déduit ni rbt | AE3: 0.13 | AF3: 0.13 | AG3: =+Y3*AE3 -> 37.1033 | AI3: =+AG3+AH3 -> 37.1033 | AJ3: VWB | AK3: 30 | AL3: 50 | AM3: =IF(AL3>0,100%,0%) -> 1 | AN3: =IF(A3>0,1,"") -> 1 | AQ3: =IF(AN3="","",+AM3/AN3) -> 1 | AR3: =IF(A3="","",VLOOKUP(A3,'Base Sites'!A:B,2,FALSE)) -> Val de Lys Automobiles | AS3: =IF(C3="VW","VOLKSWAGEN",IF(C3="SE","SEAT",IF(C3="NI","NISSAN",IF(C3="HY","HYUNDAI",IF(C3="VU","VUL",IF(C3="sk","SKODA",IF(C3="ltsk","SKODA",IF(C3="CUPRA","CUPRA",IF(C3="AUDI","AUDI",""))))))))) -> VOLKSWAGEN | AU3: =IF(A3="","",VLOOKUP(L3,'Base Vendeurs'!A:B,2,FALSE)) -> Val de Lys | AV3: =+V3+AO3 -> 380.41 | AW3: =IF(A3="","",+AV3/T3) -> 0.015415888 | AX3: =IF(AV3<0,"OUI","NON") -> NON | AY3: =+MargesVN[[#This Row],[Total COM]]+MargesVN[[#This Row],[EXT GIE]]+MargesVN[[#This Row],[Forfait immat]] -> 117.1033
A4: 60 | B4: C | C4: VW | D4: 46198 | E4: 46199 | L4: ASNMA | M4: 97 | N4: 3504 | O4: WVGZZZA15SK002127 | P4: BRANLE WILLY | Q4: T ROC | R4: 42230.67 | S4: 1083.33 | T4: =+R4+S4 -> 43314 | U4: 171 | V4: 484.39 | W4: 95 | Y4: =+V4-W4+X4 -> 389.39 | Z4: =(V4+X4)/T4 -> 0.01118322 | AA4: -5764.54 | AB4: 0 | AD4: 0 comm demandée // Forfait | AF4: 0.12 | AG4: =+Y4*AE4 -> 0 | AH4: 200 | AI4: =+AG4+AH4 -> 200 | AK4: 30 | AM4: =IF(AL4>0,100%,0%) -> 0 | AN4: =IF(A4>0,1,"") -> 1 | AQ4: =IF(AN4="","",+AM4/AN4) -> 0 | AR4: =IF(A4="","",VLOOKUP(A4,'Base Sites'!A:B,2,FALSE)) -> Val de Lys Automobiles | AS4: =IF(C4="VW","VOLKSWAGEN",IF(C4="SE","SEAT",IF(C4="NI","NISSAN",IF(C4="HY","HYUNDAI",IF(C4="VU","VUL",IF(C4="sk","SKODA",IF(C4="ltsk","SKODA",IF(C4="CUPRA","CUPRA",IF(C4="AUDI","AUDI",""))))))))) -> VOLKSWAGEN | AU4: =IF(A4="","",VLOOKUP(L4,'Base Vendeurs'!A:B,2,FALSE)) -> Val de Lys | AV4: =+V4+AO4 -> 484.39 | AW4: =IF(A4="","",+AV4/T4) -> 0.01118322 | AX4: =IF(AV4<0,"OUI","NON") -> NON | AY4: =+MargesVN[[#This Row],[Total COM]]+MargesVN[[#This Row],[EXT GIE]]+MargesVN[[#This Row],[Forfait immat]] -> 230
A5: 60 | B5: C | C5: VW | D5: 46202 | E5: 46203 | L5: ASALA | M5: 98 | N5: 3631 | O5: WVGZZZE21TE048962 | P5: VANDROMME DAVID | Q5: ID 4 | R5: 37605 | S5: 1433.33 | T5: =+R5+S5 -> 39038.33 | U5: 63 | V5: 875.76 | W5: 95 | Y5: =+V5-W5+X5 -> 780.76 | Z5: =(V5+X5)/T5 -> 0.022433337 | AA5: 0 | AB5: 0 | AE5: 0.1 | AF5: 0.12 | AG5: =+Y5*AE5 -> 78.076 | AI5: =+AG5+AH5 -> 78.076 | AJ5: VWB | AM5: =IF(AL5>0,100%,0%) -> 0 | AN5: =IF(A5>0,1,"") -> 1 | AQ5: =IF(AN5="","",+AM5/AN5) -> 0 | AR5: =IF(A5="","",VLOOKUP(A5,'Base Sites'!A:B,2,FALSE)) -> Val de Lys Automobiles | AS5: =IF(C5="VW","VOLKSWAGEN",IF(C5="SE","SEAT",IF(C5="NI","NISSAN",IF(C5="HY","HYUNDAI",IF(C5="VU","VUL",IF(C5="sk","SKODA",IF(C5="ltsk","SKODA",IF(C5="CUPRA","CUPRA",IF(C5="AUDI","AUDI",""))))))))) -> VOLKSWAGEN | AU5: =IF(A5="","",VLOOKUP(L5,'Base Vendeurs'!A:B,2,FALSE)) -> Val de Lys | AV5: =+V5+AO5 -> 875.76 | AW5: =IF(A5="","",+AV5/T5) -> 0.022433337 | AX5: =IF(AV5<0,"OUI","NON") -> NON | AY5: =+MargesVN[[#This Row],[Total COM]]+MargesVN[[#This Row],[EXT GIE]]+MargesVN[[#This Row],[Forfait immat]] -> 78.076
A6: 10 | B6: C | C6: CUPRA | D6: 46154 | E6: 46165 | K6: 0 | L6: ARNLE | M6: 572 | O6: VSSZZZK1ZNP023607 | P6: ROBERT MALIKA | Q6: Cupra el-Born | R6: 28388.74 | S6: 0 | T6: =+R6+S6 -> 28388.74 | U6: 1258 | V6: -2998.39 | W6: 0 | Y6: =+V6-W6+X6 -> -2998.39 | Z6: =(V6+X6)/T6 -> -0.10561899 | AA6: 0 | AB6: 0 | AD6: marge négative // manque signatures | AF6: 0.1 | AG6: =+Y6*AE6 -> 0 | AH6: 150 | AI6: =+AG6+AH6 -> 150 | AK6: 0 | AL6: 50 | AM6: =IF(AL6>0,100%,0%) -> 1 | AN6: =IF(A6>0,1,"") -> 1 | AQ6: =IF(AN6="","",+AM6/AN6) -> 1 | AR6: =IF(A6="","",VLOOKUP(A6,'Base Sites'!A:B,2,FALSE)) -> Valauto Roncq | AS6: =IF(C6="VW","VOLKSWAGEN",IF(C6="SE","SEAT",IF(C6="NI","NISSAN",IF(C6="HY","HYUNDAI",IF(C6="VU","VUL",IF(C6="sk","SKODA",IF(C6="ltsk","SKODA",IF(C6="CUPRA","CUPRA",IF(C6="AUDI","AUDI",""))))))))) -> CUPRA | AU6: =IF(A6="","",VLOOKUP(L6,'Base Vendeurs'!A:B,2,FALSE)) -> Valauto Arras | AV6: =+V6+AO6 -> -2998.39 | AW6: =IF(A6="","",+AV6/T6) -> -0.10561899 | AX6: =IF(AV6<0,"OUI","NON") -> OUI | AY6: =+MargesVN[[#This Row],[Total COM]]+MargesVN[[#This Row],[EXT GIE]]+MargesVN[[#This Row],[Forfait immat]] -> 200
A7: 10 | B7: C | C7: VW | D7: 46098 | E7: 46099 | K7: 0 | L7: RQGDI | M7: 594 | N7: 511408 | O7: WVGZZZE20RP506374 | P7: CH CONSULTING | Q7: ID 5 | R7: 41363.33 | S7: 1433.33 | T7: =+R7+S7 -> 42796.66 | U7: 413 | V7: -6904.53 | W7: 95 | Y7: =+V7-W7+X7 -> -6999.53 | Z7: =(V7+X7)/T7 -> -0.16133338 | AA7: -2995.77 | AB7: 0 | AD7: marge négative // challenge // VN vendu 38493,76€ au lieu de 38990€ | AF7: 0.13 | AG7: =+Y7*AE7 -> 0 | AH7: 200 | AI7: =+AG7+AH7 -> 200 | AJ7: VWB | AL7: 50 | AM7: =IF(AL7>0,100%,0%) -> 1 | AN7: =IF(A7>0,1,"") -> 1 | AQ7: =IF(AN7="","",+AM7/AN7) -> 1 | AR7: =IF(A7="","",VLOOKUP(A7,'Base Sites'!A:B,2,FALSE)) -> Valauto Roncq | AS7: =IF(C7="VW","VOLKSWAGEN",IF(C7="SE","SEAT",IF(C7="NI","NISSAN",IF(C7="HY","HYUNDAI",IF(C7="VU","VUL",IF(C7="sk","SKODA",IF(C7="ltsk","SKODA",IF(C7="CUPRA","CUPRA",IF(C7="AUDI","AUDI",""))))))))) -> VOLKSWAGEN | AU7: =IF(A7="","",VLOOKUP(L7,'Base Vendeurs'!A:B,2,FALSE)) -> Valauto Roncq VW | AV7: =+V7+AO7 -> -6904.53 | AW7: =IF(A7="","",+AV7/T7) -> -0.16133338 | AX7: =IF(AV7<0,"OUI","NON") -> OUI | AY7: =+MargesVN[[#This Row],[Total COM]]+MargesVN[[#This Row],[EXT GIE]]+MargesVN[[#This Row],[Forfait immat]] -> 250
A8: 10 | B8: C | C8: SK | D8: 46069 | E8: 46070 | K8: 0 | L8: RQTHC | M8: 609 | N8: 511811 | O8: TMBJB7PSXST106889 | P8: PARIS TERMINAL SA | Q8: KODIAQ | R8: 40833.33 | S8: 2775 | T8: =+R8+S8 -> 43608.33 | U8: 146 | V8: 1189.23 | W8: 35.01 | Y8: =+V8-W8+X8 -> 1154.22 | Z8: =(V8+X8)/T8 -> 0.027270707 | AA8: -4712 | AB8: 0 | AE8: 0.13 | AF8: 0.13 | AG8: =+Y8*AE8 -> 150.0486 | AI8: =+AG8+AH8 -> 150.0486 | AM8: =IF(AL8>0,100%,0%) -> 0 | AN8: =IF(A8>0,1,"") -> 1 | AQ8: =IF(AN8="","",+AM8/AN8) -> 0 | AR8: =IF(A8="","",VLOOKUP(A8,'Base Sites'!A:B,2,FALSE)) -> Valauto Roncq | AS8: =IF(C8="VW","VOLKSWAGEN",IF(C8="SE","SEAT",IF(C8="NI","NISSAN",IF(C8="HY","HYUNDAI",IF(C8="VU","VUL",IF(C8="sk","SKODA",IF(C8="ltsk","SKODA",IF(C8="CUPRA","CUPRA",IF(C8="AUDI","AUDI",""))))))))) -> SKODA | AU8: =IF(A8="","",VLOOKUP(L8,'Base Vendeurs'!A:B,2,FALSE)) -> Valauto Roncq Skoda | AV8: =+V8+AO8 -> 1189.23 | AW8: =IF(A8="","",+AV8/T8) -> 0.027270707 | AX8: =IF(AV8<0,"OUI","NON") -> NON | AY8: =+MargesVN[[#This Row],[Total COM]]+MargesVN[[#This Row],[EXT GIE]]+MargesVN[[#This Row],[Forfait immat]] -> 150.0486
A9: 10 | B9: NP | C9: VW | D9: 46078 | E9: 46076 | I9: x | K9: 24432.88 | L9: LTBDU | M9: 612 | O9: WVGZZZCS9TY011112 | P9: BAILLEUL KLEBER | Q9: TAIGO | R9: 27264 | S9: 922.83 | T9: =+R9+S9 -> 28186.83 | U9: 118 | V9: 964.11 | W9: 95 | Y9: =+V9-W9+X9 -> 869.11 | Z9: =(V9+X9)/T9 -> 0.034204272 | AA9: -2921.79 | AB9: 0 | AD9: solde client mq financement | AE9: 0.13 | AF9: 0.13 | AG9: =+Y9*AE9 -> 112.9843 | AI9: =+AG9+AH9 -> 112.9843 | AK9: 30 | AL9: 50 | AM9: =IF(AL9>0,100%,0%) -> 1 | AN9: =IF(A9>0,1,"") -> 1 | AQ9: =IF(AN9="","",+AM9/AN9) -> 1 | AR9: =IF(A9="","",VLOOKUP(A9,'Base Sites'!A:B,2,FALSE)) -> Valauto Roncq | AS9: =IF(C9="VW","VOLKSWAGEN",IF(C9="SE","SEAT",IF(C9="NI","NISSAN",IF(C9="HY","HYUNDAI",IF(C9="VU","VUL",IF(C9="sk","SKODA",IF(C9="ltsk","SKODA",IF(C9="CUPRA","CUPRA",IF(C9="AUDI","AUDI",""))))))))) -> VOLKSWAGEN | AU9: =IF(A9="","",VLOOKUP(L9,'Base Vendeurs'!A:B,2,FALSE)) -> Valauto Lambersart VW | AV9: =+V9+AO9 -> 964.11 | AW9: =IF(A9="","",+AV9/T9) -> 0.034204272 | AX9: =IF(AV9<0,"OUI","NON") -> NON | AY9: =+MargesVN[[#This Row],[Total COM]]+MargesVN[[#This Row],[EXT GIE]]+MargesVN[[#This Row],[Forfait immat]] -> 192.9843
A10: 10 | B10: C | C10: VW | D10: 46064 | E10: 46064 | K10: 0 | L10: RXNTA | M10: 615 | N10: 515962 | O10: WVGZZZCT4TW424074 | P10: DELSARTE BERTIL | Q10: TIGUAN | R10: 48155 | S10: 5220.84 | T10: =+R10+S10 -> 53375.84 | U10: 57 | V10: 1025.17 | W10: 95 | Y10: =+V10-W10+X10 -> 930.17 | Z10: =(V10+X10)/T10 -> 0.01920663 | AA10: -4803.83 | AB10: -2000 | AE10: 0.13 | AF10: 0.13 | AG10: =+Y10*AE10 -> 120.9221 | AI10: =+AG10+AH10 -> 120.9221 | AK10: 30 | AM10: =IF(AL10>0,100%,0%) -> 0 | AN10: =IF(A10>0,1,"") -> 1 | AQ10: =IF(AN10="","",+AM10/AN10) -> 0 | AR10: =IF(A10="","",VLOOKUP(A10,'Base Sites'!A:B,2,FALSE)) -> Valauto Roncq | AS10: =IF(C10="VW","VOLKSWAGEN",IF(C10="SE","SEAT",IF(C10="NI","NISSAN",IF(C10="HY","HYUNDAI",IF(C10="VU","VUL",IF(C10="sk","SKODA",IF(C10="ltsk","SKODA",IF(C10="CUPRA","CUPRA",IF(C10="AUDI","AUDI",""))))))))) -> VOLKSWAGEN | AU10: =IF(A10="","",VLOOKUP(L10,'Base Vendeurs'!A:B,2,FALSE)) -> Valauto Roubaix | AV10: =+V10+AO10 -> 1025.17 | AW10: =IF(A10="","",+AV10/T10) -> 0.01920663 | AX10: =IF(AV10<0,"OUI","NON") -> NON | AY10: =+MargesVN[[#This Row],[Total COM]]+MargesVN[[#This Row],[EXT GIE]]+MargesVN[[#This Row],[Forfait immat]] -> 150.9221
A11: 10 | B11: C | C11: VW | D11: 46128 | E11: 46121 | L11: RXNTA | M11: 616 | O11: WVGZZZCT5TW519887 | P11: OUALI SLIMANE | Q11: TIGUAN | R11: 44655 | S11: 8791.67 | T11: =+R11+S11 -> 53446.67 | U11: 73 | V11: 1382.28 | W11: 95 | Y11: =+V11-W11+X11 -> 1287.28 | Z11: =(V11+X11)/T11 -> 0.02586279 | AA11: -5810.2 | AB11: 0 | AE11: 0.13 | AF11: 0.13 | AG11: =+Y11*AE11 -> 167.3464 | AI11: =+AG11+AH11 -> 167.3464 | AK11: 30 | AM11: =IF(AL11>0,100%,0%) -> 0 | AN11: =IF(A11>0,1,"") -> 1 | AQ11: =IF(AN11="","",+AM11/AN11) -> 0 | AR11: =IF(A11="","",VLOOKUP(A11,'Base Sites'!A:B,2,FALSE)) -> Valauto Roncq | AS11: =IF(C11="VW","VOLKSWAGEN",IF(C11="SE","SEAT",IF(C11="NI","NISSAN",IF(C11="HY","HYUNDAI",IF(C11="VU","VUL",IF(C11="sk","SKODA",IF(C11="ltsk","SKODA",IF(C11="CUPRA","CUPRA",IF(C11="AUDI","AUDI",""))))))))) -> VOLKSWAGEN | AU11: =IF(A11="","",VLOOKUP(L11,'Base Vendeurs'!A:B,2,FALSE)) -> Valauto Roubaix | AV11: =+V11+AO11 -> 1382.28 | AW11: =IF(A11="","",+AV11/T11) -> 0.02586279 | AX11: =IF(AV11<0,"OUI","NON") -> NON | AY11: =+MargesVN[[#This Row],[Total COM]]+MargesVN[[#This Row],[EXT GIE]]+MargesVN[[#This Row],[Forfait immat]] -> 197.3464
A12: 10 | B12: C | C12: VW | D12: 46136 | E12: 46144 | K12: 0 | L12: RXNTA | M12: 619 | N12: 516067 | O12: WVGZZZC17TY067136 | P12: TOUAF AHMED | Q12: T CROSS | R12: 28389 | S12: -1516.67 | T12: =+R12+S12 -> 26872.33 | U12: 46 | V12: 1076.06 | W12: 95 | Y12: =+V12-W12+X12 -> 981.06 | Z12: =(V12+X12)/T12 -> 0.04004342 | AA12: 0 | AB12: -3349.99 | AE12: 0.1 | AF12: 0.1 | AG12: =+Y12*AE12 -> 98.106 | AI12: =+AG12+AH12 -> 98.106 | AK12: 30 | AM12: =IF(AL12>0,100%,0%) -> 0 | AN12: =IF(A12>0,1,"") -> 1 | AQ12: =IF(AN12="","",+AM12/AN12) -> 0 | AR12: =IF(A12="","",VLOOKUP(A12,'Base Sites'!A:B,2,FALSE)) -> Valauto Roncq | AS12: =IF(C12="VW","VOLKSWAGEN",IF(C12="SE","SEAT",IF(C12="NI","NISSAN",IF(C12="HY","HYUNDAI",IF(C12="VU","VUL",IF(C12="sk","SKODA",IF(C12="ltsk","SKODA",IF(C12="CUPRA","CUPRA",IF(C12="AUDI","AUDI",""))))))))) -> VOLKSWAGEN | AU12: =IF(A12="","",VLOOKUP(L12,'Base Vendeurs'!A:B,2,FALSE)) -> Valauto Roubaix | AV12: =+V12+AO12 -> 1076.06 | AW12: =IF(A12="","",+AV12/T12) -> 0.04004342 | AX12: =IF(AV12<0,"OUI","NON") -> NON | AY12: =+MargesVN[[#This Row],[Total COM]]+MargesVN[[#This Row],[EXT GIE]]+MargesVN[[#This Row],[Forfait immat]] -> 128.106
A13: 10 | B13: C | C13: VW | D13: 46177 | E13: 46177 | K13: 0 | L13: RXNTA | M13: 620 | O13: WVGZZZA26TV038191 | P13: CRENEAU ERIC | Q13: T ROC | R13: 24380.67 | S13: 808.33 | T13: =+R13+S13 -> 25189 | U13: 62 | V13: 657.87 | W13: 95 | Y13: =+V13-W13+X13 -> 562.87 | Z13: =(V13+X13)/T13 -> 0.026117353 | AA13: 0 | AB13: -1250 | AE13: 0.13 | AF13: 0.12 | AG13: =+Y13*AE13 -> 73.1731 | AI13: =+AG13+AH13 -> 73.1731 | AK13: 30 | AM13: =IF(AL13>0,100%,0%) -> 0 | AN13: =IF(A13>0,1,"") -> 1 | AQ13: =IF(AN13="","",+AM13/AN13) -> 0 | AR13: =IF(A13="","",VLOOKUP(A13,'Base Sites'!A:B,2,FALSE)) -> Valauto Roncq | AS13: =IF(C13="VW","VOLKSWAGEN",IF(C13="SE","SEAT",IF(C13="NI","NISSAN",IF(C13="HY","HYUNDAI",IF(C13="VU","VUL",IF(C13="sk","SKODA",IF(C13="ltsk","SKODA",IF(C13="CUPRA","CUPRA",IF(C13="AUDI","AUDI",""))))))))) -> VOLKSWAGEN | AU13: =IF(A13="","",VLOOKUP(L13,'Base Vendeurs'!A:B,2,FALSE)) -> Valauto Roubaix | AV13: =+V13+AO13 -> 657.87 | AW13: =IF(A13="","",+AV13/T13) -> 0.026117353 | AX13: =IF(AV13<0,"OUI","NON") -> NON | AY13: =+MargesVN[[#This Row],[Total COM]]+MargesVN[[#This Row],[EXT GIE]]+MargesVN[[#This Row],[Forfait immat]] -> 103.1731
A14: 10 | B14: NL | C14: CUPRA | D14: 46148 | L14: VSJTI | M14: 621 | O14: VSSZZZP4T1068908 | P14: PROLYNE | Q14: TERRAMAR | R14: 49204.33 | S14: 1612.5 | T14: =+R14+S14 -> 50816.83 | U14: 20 | V14: 331.87 | W14: 22 | Y14: =+V14-W14+X14 -> 309.87 | Z14: =(V14+X14)/T14 -> 0.0065307104 | AA14: 0 | AB14: 611.67 | AF14: 0 | AG14: =+Y14*AE14 -> 0 | AI14: =+AG14+AH14 -> 0 | AK14: 0 | AL14: 0 | AM14: =IF(AL14>0,100%,0%) -> 0 | AN14: =IF(A14>0,1,"") -> 1 | AQ14: =IF(AN14="","",+AM14/AN14) -> 0 | AR14: =IF(A14="","",VLOOKUP(A14,'Base Sites'!A:B,2,FALSE)) -> Valauto Roncq | AS14: =IF(C14="VW","VOLKSWAGEN",IF(C14="SE","SEAT",IF(C14="NI","NISSAN",IF(C14="HY","HYUNDAI",IF(C14="VU","VUL",IF(C14="sk","SKODA",IF(C14="ltsk","SKODA",IF(C14="CUPRA","CUPRA",IF(C14="AUDI","AUDI",""))))))))) -> CUPRA | AU14: =IF(A14="","",VLOOKUP(L14,'Base Vendeurs'!A:B,2,FALSE)) -> Sociétés EST | AV14: =+V14+AO14 -> 331.87 | AW14: =IF(A14="","",+AV14/T14) -> 0.0065307104 | AX14: =IF(AV14<0,"OUI","NON") -> NON | AY14: =+MargesVN[[#This Row],[Total COM]]+MargesVN[[#This Row],[EXT GIE]]+MargesVN[[#This Row],[Forfait immat]] -> 0
A15: 70 | B15: C | C15: HY | D15: 46058 | E15: 46053 | K15: 0 | L15: LETLE | M15: 5059 | N15: 2104841989 | O15: KMHKR81EFPU180873 | P15: MERIEN VALENTIN | Q15: IONIQ | R15: 49500.48 | S15: 750 | T15: =+R15+S15 -> 50250.48 | U15: 986 | V15: -12931.51 | W15: -0.01 | Y15: =+V15-W15+X15 -> -12931.5 | Z15: =(V15+X15)/T15 -> -0.25734102 | AA15: -4681.54 | AB15: 0 | AD15: marge négative // Vieux stock | AF15: 0.13 | AG15: =+Y15*AE15 -> 0 | AH15: 300 | AI15: =+AG15+AH15 -> 300 | AK15: 0 | AL15: 100 | AM15: =IF(AL15>0,100%,0%) -> 1 | AN15: =IF(A15>0,1,"") -> 1 | AQ15: =IF(AN15="","",+AM15/AN15) -> 1 | AR15: =IF(A15="","",VLOOKUP(A15,'Base Sites'!A:B,2,FALSE)) -> Valauto Lomme | AS15: =IF(C15="VW","VOLKSWAGEN",IF(C15="SE","SEAT",IF(C15="NI","NISSAN",IF(C15="HY","HYUNDAI",IF(C15="VU","VUL",IF(C15="sk","SKODA",IF(C15="ltsk","SKODA",IF(C15="CUPRA","CUPRA",IF(C15="AUDI","AUDI",""))))))))) -> HYUNDAI | AU15: =IF(A15="","",VLOOKUP(L15,'Base Vendeurs'!A:B,2,FALSE)) -> Hyundai Lomme | AV15: =+V15+AO15 -> -12931.51 | AW15: =IF(A15="","",+AV15/T15) -> -0.25734102 | AX15: =IF(AV15<0,"OUI","NON") -> OUI | AY15: =+MargesVN[[#This Row],[Total COM]]+MargesVN[[#This Row],[EXT GIE]]+MargesVN[[#This Row],[Forfait immat]] -> 400
A16: 70 | B16: C | C16: HY | D16: 46169 | E16: 46172 | K16: 0 | L16: LELBO | M16: 5084 | N16: 2104860376 | O16: TMAK281GFPJ093622 | P16: SONNEVILLE MARYSE | Q16: KONA | R16: 34754.09 | S16: 0 | T16: =+R16+S16 -> 34754.09 | U16: 1072 | V16: -11953.03 | W16: 0 | Y16: =+V16-W16+X16 -> -11953.03 | Z16: =(V16+X16)/T16 -> -0.34393161 | AA16: -2084.76 | AB16: 0 | AD16: marge négative // Forfait vieux stock | AF16: 0.13 | AG16: =+Y16*AE16 -> 0 | AH16: 300 | AI16: =+AG16+AH16 -> 300 | AJ16: Hyundai Finance | AK16: 0 | AL16: 0 | AM16: =IF(AL16>0,100%,0%) -> 1 | AN16: =IF(A16>0,1,"") -> 1 | AQ16: =IF(AN16="","",+AM16/AN16) -> 1 | AR16: =IF(A16="","",VLOOKUP(A16,'Base Sites'!A:B,2,FALSE)) -> Valauto Lomme | AS16: =IF(C16="VW","VOLKSWAGEN",IF(C16="SE","SEAT",IF(C16="NI","NISSAN",IF(C16="HY","HYUNDAI",IF(C16="VU","VUL",IF(C16="sk","SKODA",IF(C16="ltsk","SKODA",IF(C16="CUPRA","CUPRA",IF(C16="AUDI","AUDI",""))))))))) -> HYUNDAI | AU16: =IF(A16="","",VLOOKUP(L16,'Base Vendeurs'!A:B,2,FALSE)) -> Hyundai Lomme | AV16: =+V16+AO16 -> -11953.03 | AW16: =IF(A16="","",+AV16/T16) -> -0.34393161 | AX16: =IF(AV16<0,"OUI","NON") -> OUI | AY16: =+MargesVN[[#This Row],[Total COM]]+MargesVN[[#This Row],[EXT GIE]]+MargesVN[[#This Row],[Forfait immat]] -> 300
A17: 70 | B17: C | C17: HY | D17: 46119 | E17: 46121 | K17: 0 | L17: LEGCH | M17: 5141 | N17: 2104937191 | O17: TMAH881A9RJ002231 | P17: CARRE DIDIER | Q17: KONA | R17: 34670.76 | S17: 541.67 | T17: =+R17+S17 -> 35212.43 | U17: 946 | V17: -3575.79 | W17: 0 | Y17: =+V17-W17+X17 -> -3575.79 | Z17: =(V17+X17)/T17 -> -0.10154908 | AA17: -6795.26 | AB17: 0 | AD17: Marge négative // Forfait vieux stock // 1 AN pour livrer | AF17: 0.13 | AG17: =+Y17*AE17 -> 0 | AI17: =+AG17+AH17 -> 0 | AJ17: Hyundai Finance | AK17: 0 | AL17: 50 | AM17: =IF(AL17>0,100%,0%) -> 1 | AN17: =IF(A17>0,1,"") -> 1 | AQ17: =IF(AN17="","",+AM17/AN17) -> 1 | AR17: =IF(A17="","",VLOOKUP(A17,'Base Sites'!A:B,2,FALSE)) -> Valauto Lomme | AS17: =IF(C17="VW","VOLKSWAGEN",IF(C17="SE","SEAT",IF(C17="NI","NISSAN",IF(C17="HY","HYUNDAI",IF(C17="VU","VUL",IF(C17="sk","SKODA",IF(C17="ltsk","SKODA",IF(C17="CUPRA","CUPRA",IF(C17="AUDI","AUDI",""))))))))) -> HYUNDAI | AU17: =IF(A17="","",VLOOKUP(L17,'Base Vendeurs'!A:B,2,FALSE)) -> Hyundai Lomme | AV17: =+V17+AO17 -> -3575.79 | AW17: =IF(A17="","",+AV17/T17) -> -0.10154908 | AX17: =IF(AV17<0,"OUI","NON") -> OUI | AY17: =+MargesVN[[#This Row],[Total COM]]+MargesVN[[#This Row],[EXT GIE]]+MargesVN[[#This Row],[Forfait immat]] -> 50
A18: 70 | B18: C | C18: HY | D18: 46063 | E18: 46066 | K18: 0 | L18: LETLE | M18: 5258 | N18: 2104698357 | O18: TMAH381BGPJ154164 | P18: PRUD'HOMME DOMINIQUE | Q18: I30 | R18: 25129.09 | S18: 0 | T18: =+R18+S18 -> 25129.09 | U18: 806 | V18: -1615.07 | Y18: =+V18-W18+X18 -> -1615.07 | Z18: =(V18+X18)/T18 -> -0.064270931 | AA18: -2322.66 | AB18: 0 | AD18: marge négative // Challenge vieux stock | AF18: 0.13 | AG18: =+Y18*AE18 -> 0 | AH18: 300 | AI18: =+AG18+AH18 -> 300 | AK18: 0 | AL18: 0 | AM18: =IF(AL18>0,100%,0%) -> 1 | AN18: =IF(A18>0,1,"") -> 1 | AQ18: =IF(AN18="","",+AM18/AN18) -> 1 | AR18: =IF(A18="","",VLOOKUP(A18,'Base Sites'!A:B,2,FALSE)) -> Valauto Lomme | AS18: =IF(C18="VW","VOLKSWAGEN",IF(C18="SE","SEAT",IF(C18="NI","NISSAN",IF(C18="HY","HYUNDAI",IF(C18="VU","VUL",IF(C18="sk","SKODA",IF(C18="ltsk","SKODA",IF(C18="CUPRA","CUPRA",IF(C18="AUDI","AUDI",""))))))))) -> HYUNDAI | AU18: =IF(A18="","",VLOOKUP(L18,'Base Vendeurs'!A:B,2,FALSE)) -> Hyundai Lomme | AV18: =+V18+AO18 -> -1615.07 | AW18: =IF(A18="","",+AV18/T18) -> -0.064270931 | AX18: =IF(AV18<0,"OUI","NON") -> OUI | AY18: =+MargesVN[[#This Row],[Total COM]]+MargesVN[[#This Row],[EXT GIE]]+MargesVN[[#This Row],[Forfait immat]] -> 300
A19: 70 | B19: C | C19: HY | D19: 46163 | E19: 46164 | L19: LELBO | M19: 5270 | N19: 2105035660 | O19: KMHKR81FPPU181397 | P19: LILA | Q19: IONIQ | R19: 53083.81 | S19: 333.33 | T19: =+R19+S19 -> 53417.14 | U19: 896 | V19: -8143.94 | W19: 0.01 | Y19: =+V19-W19+X19 -> -8143.95 | Z19: =(V19+X19)/T19 -> -0.1524593 | AA19: -17930.68 | AB19: 0 | AD19: marge négative // Forfait vieux stock | AF19: 0.13 | AG19: =+Y19*AE19 -> 0 | AH19: 300 | AI19: =+AG19+AH19 -> 300 | AJ19: Banque | AK19: 0 | AL19: 0 | AM19: =IF(AL19>0,100%,0%) -> 1 | AN19: =IF(A19>0,1,"") -> 1 | AQ19: =IF(AN19="","",+AM19/AN19) -> 1 | AR19: =IF(A19="","",VLOOKUP(A19,'Base Sites'!A:B,2,FALSE)) -> Valauto Lomme | AS19: =IF(C19="VW","VOLKSWAGEN",IF(C19="SE","SEAT",IF(C19="NI","NISSAN",IF(C19="HY","HYUNDAI",IF(C19="VU","VUL",IF(C19="sk","SKODA",IF(C19="ltsk","SKODA",IF(C19="CUPRA","CUPRA",IF(C19="AUDI","AUDI",""))))))))) -> HYUNDAI | AU19: =IF(A19="","",VLOOKUP(L19,'Base Vendeurs'!A:B,2,FALSE)) -> Hyundai Lomme | AV19: =+V19+AO19 -> -8143.94 | AW19: =IF(A19="","",+AV19/T19) -> -0.1524593 | AX19: =IF(AV19<0,"OUI","NON") -> OUI | AY19: =+MargesVN[[#This Row],[Total COM]]+MargesVN[[#This Row],[EXT GIE]]+MargesVN[[#This Row],[Forfait immat]] -> 300
A20: 70 | B20: C | C20: HY | D20: 46163 | E20: 46164 | L20: LELBO | M20: 5304 | N20: 2105046851 | O20: KMHKR81EFPU225522 | P20: LILA | Q20: IONIQ | R20: 49833.81 | S20: 0 | T20: =+R20+S20 -> 49833.81 | U20: 864 | V20: -8054.43 | W20: 0 | Y20: =+V20-W20+X20 -> -8054.43 | Z20: =(V20+X20)/T20 -> -0.16162581 | AA20: -11808.7 | AB20: 0 | AD20: marge négative // Forfait vieux stock | AF20: 0.13 | AG20: =+Y20*AE20 -> 0 | AH20: 300 | AI20: =+AG20+AH20 -> 300 | AJ20: Banque | AK20: 0 | AL20: 0 | AM20: =IF(AL20>0,100%,0%) -> 1 | AN20: =IF(A20>0,1,"") -> 1 | AQ20: =IF(AN20="","",+AM20/AN20) -> 1 | AR20: =IF(A20="","",VLOOKUP(A20,'Base Sites'!A:B,2,FALSE)) -> Valauto Lomme | AS20: =IF(C20="VW","VOLKSWAGEN",IF(C20="SE","SEAT",IF(C20="NI","NISSAN",IF(C20="HY","HYUNDAI",IF(C20="VU","VUL",IF(C20="sk","SKODA",IF(C20="ltsk","SKODA",IF(C20="CUPRA","CUPRA",IF(C20="AUDI","AUDI",""))))))))) -> HYUNDAI | AU20: =IF(A20="","",VLOOKUP(L20,'Base Vendeurs'!A:B,2,FALSE)) -> Hyundai Lomme | AV20: =+V20+AO20 -> -8054.43 | AW20: =IF(A20="","",+AV20/T20) -> -0.16162581 | AX20: =IF(AV20<0,"OUI","NON") -> OUI | AY20: =+MargesVN[[#This Row],[Total COM]]+MargesVN[[#This Row],[EXT GIE]]+MargesVN[[#This Row],[Forfait immat]] -> 300
A21: 70 | B21: C | C21: HY | D21: 46163 | E21: 46164 | L21: LELBO | M21: 5308 | N21: 2105048641 | O21: KMHKR81FPPU210158 | P21: LILA | Q21: IONIQ | R21: 52750.48 | S21: 750 | T21: =+R21+S21 -> 53500.48 | U21: 862 | V21: -8130.31 | W21: 0 | Y21: =+V21-W21+X21 -> -8130.31 | Z21: =(V21+X21)/T21 -> -0.15196705 | AA21: -12677.69 | AB21: 0 | AD21: marge négative // Forfait vieux stock | AF21: 0.13 | AG21: =+Y21*AE21 -> 0 | AH21: 300 | AI21: =+AG21+AH21 -> 300 | AJ21: Banque | AK21: 0 | AL21: 0 | AM21: =IF(AL21>0,100%,0%) -> 1 | AN21: =IF(A21>0,1,"") -> 1 | AQ21: =IF(AN21="","",+AM21/AN21) -> 1 | AR21: =IF(A21="","",VLOOKUP(A21,'Base Sites'!A:B,2,FALSE)) -> Valauto Lomme | AS21: =IF(C21="VW","VOLKSWAGEN",IF(C21="SE","SEAT",IF(C21="NI","NISSAN",IF(C21="HY","HYUNDAI",IF(C21="VU","VUL",IF(C21="sk","SKODA",IF(C21="ltsk","SKODA",IF(C21="CUPRA","CUPRA",IF(C21="AUDI","AUDI",""))))))))) -> HYUNDAI | AU21: =IF(A21="","",VLOOKUP(L21,'Base Vendeurs'!A:B,2,FALSE)) -> Hyundai Lomme | AV21: =+V21+AO21 -> -8130.31 | AW21: =IF(A21="","",+AV21/T21) -> -0.15196705 | AX21: =IF(AV21<0,"OUI","NON") -> OUI | AY21: =+MargesVN[[#This Row],[Total COM]]+MargesVN[[#This Row],[EXT GIE]]+MargesVN[[#This Row],[Forfait immat]] -> 300
A22: 70 | B22: C | C22: HY | D22: 46058 | E22: 46052 | K22: 0 | L22: LELBO | M22: 5368 | N22: 2105174011 | O22: TMAH351BGPJ227180 | P22: RIBEAUCOURT EDOUARD | Q22: I30 | R22: 24295.76 | S22: 583.33 | T22: =+R22+S22 -> 24879.09 | U22: 685 | V22: -2510.82 | W22: 0 | Y22: =+V22-W22+X22 -> -2510.82 | Z22: =(V22+X22)/T22 -> -0.10092089 | AA22: -2818.02 | AB22: 0 | AD22: marge négative // Challenge vieux stock | AF22: 0.13 | AG22: =+Y22*AE22 -> 0 | AH22: 300 | AI22: =+AG22+AH22 -> 300 | AK22: 0 | AL22: 0 | AM22: =IF(AL22>0,100%,0%) -> 1 | AN22: =IF(A22>0,1,"") -> 1 | AQ22: =IF(AN22="","",+AM22/AN22) -> 1 | AR22: =IF(A22="","",VLOOKUP(A22,'Base Sites'!A:B,2,FALSE)) -> Valauto Lomme | AS22: =IF(C22="VW","VOLKSWAGEN",IF(C22="SE","SEAT",IF(C22="NI","NISSAN",IF(C22="HY","HYUNDAI",IF(C22="VU","VUL",IF(C22="sk","SKODA",IF(C22="ltsk","SKODA",IF(C22="CUPRA","CUPRA",IF(C22="AUDI","AUDI",""))))))))) -> HYUNDAI | AU22: =IF(A22="","",VLOOKUP(L22,'Base Vendeurs'!A:B,2,FALSE)) -> Hyundai Lomme | AV22: =+V22+AO22 -> -2510.82 | AW22: =IF(A22="","",+AV22/T22) -> -0.10092089 | AX22: =IF(AV22<0,"OUI","NON") -> OUI | AY22: =+MargesVN[[#This Row],[Total COM]]+MargesVN[[#This Row],[EXT GIE]]+MargesVN[[#This Row],[Forfait immat]] -> 300
A23: 70 | B23: C | C23: HY | D23: 46175 | E23: 46176 | K23: 0 | L23: LELBO | M23: 5393 | N23: 2105209894 | O23: KMHM541A9PA017624 | P23: BELLAY CHRISTOPHE | Q23: IONIQ | R23: 51167.14 | S23: 825 | T23: =+R23+S23 -> 51992.14 | U23: 771 | V23: -6596.57 | W23: 0 | Y23: =+V23-W23+X23 -> -6596.57 | Z23: =(V23+X23)/T23 -> -0.12687629 | AA23: -9944.77 | AB23: 0 | AD23: marge négative // Challenge vieux stock | AF23: 0.13 | AG23: =+Y23*AE23 -> 0 | AH23: 300 | AI23: =+AG23+AH23 -> 300 | AK23: 0 | AM23: =IF(AL23>0,100%,0%) -> 0 | AN23: =IF(A23>0,1,"") -> 1 | AQ23: =IF(AN23="","",+AM23/AN23) -> 0 | AR23: =IF(A23="","",VLOOKUP(A23,'Base Sites'!A:B,2,FALSE)) -> Valauto Lomme | AS23: =IF(C23="VW","VOLKSWAGEN",IF(C23="SE","SEAT",IF(C23="NI","NISSAN",IF(C23="HY","HYUNDAI",IF(C23="VU","VUL",IF(C23="sk","SKODA",IF(C23="ltsk","SKODA",IF(C23="CUPRA","CUPRA",IF(C23="AUDI","AUDI",""))))))))) -> HYUNDAI | AU23: =IF(A23="","",VLOOKUP(L23,'Base Vendeurs'!A:B,2,FALSE)) -> Hyundai Lomme | AV23: =+V23+AO23 -> -6596.57 | AW23: =IF(A23="","",+AV23/T23) -> -0.12687629 | AX23: =IF(AV23<0,"OUI","NON") -> OUI | AY23: =+MargesVN[[#This Row],[Total COM]]+MargesVN[[#This Row],[EXT GIE]]+MargesVN[[#This Row],[Forfait immat]] -> 300
A24: 70 | B24: C | C24: HY | D24: 46024 | E24: 46027 | K24: 0 | L24: LEGCH | M24: 5519 | N24: 2105325853 | O24: NLHBN51H8SZ493976 | P24: DELMARE ERIC | Q24: I20 | R24: 16545.76 | S24: 458.33 | T24: =+R24+S24 -> 17004.09 | U24: 519 | V24: 739.64 | W24: 0 | Y24: =+V24-W24+X24 -> 739.64 | Z24: =(V24+X24)/T24 -> 0.04349777 | AA24: -792 | AB24: 0 | AE24: 0.13 | AF24: 0.13 | AG24: =+Y24*AE24 -> 96.1532 | AI24: =+AG24+AH24 -> 96.1532 | AK24: 0 | AL24: 100 | AM24: =IF(AL24>0,100%,0%) -> 1 | AN24: =IF(A24>0,1,"") -> 1 | AQ24: =IF(AN24="","",+AM24/AN24) -> 1 | AR24: =IF(A24="","",VLOOKUP(A24,'Base Sites'!A:B,2,FALSE)) -> Valauto Lomme | AS24: =IF(C24="VW","VOLKSWAGEN",IF(C24="SE","SEAT",IF(C24="NI","NISSAN",IF(C24="HY","HYUNDAI",IF(C24="VU","VUL",IF(C24="sk","SKODA",IF(C24="ltsk","SKODA",IF(C24="CUPRA","CUPRA",IF(C24="AUDI","AUDI",""))))))))) -> HYUNDAI | AU24: =IF(A24="","",VLOOKUP(L24,'Base Vendeurs'!A:B,2,FALSE)) -> Hyundai Lomme | AV24: =+V24+AO24 -> 739.64 | AW24: =IF(A24="","",+AV24/T24) -> 0.04349777 | AX24: =IF(AV24<0,"OUI","NON") -> NON | AY24: =+MargesVN[[#This Row],[Total COM]]+MargesVN[[#This Row],[EXT GIE]]+MargesVN[[#This Row],[Forfait immat]] -> 196.1532
A25: 70 | B25: C | C25: HY | D25: 46163 | E25: 46164 | K25: 0 | L25: LELBO | M25: 5530 | N25: 2105362616 | O25: KMHKR81A2SU316365 | P25: NOUGAOUI NABIL | Q25: IONIQ | R25: 49042.14 | S25: 575 | T25: =+R25+S25 -> 49617.14 | U25: 631 | V25: -4215.91 | W25: 0 | Y25: =+V25-W25+X25 -> -4215.91 | Z25: =(V25+X25)/T25 -> -0.084968823 | AA25: -11650.7 | AB25: 0 | AD25: mage négative // Forfait vieux stock | AF25: 0.13 | AG25: =+Y25*AE25 -> 0 | AH25: 300 | AI25: =+AG25+AH25 -> 300 | AJ25: Banque | AK25: 0 | AL25: 0 | AM25: =IF(AL25>0,100%,0%) -> 1 | AN25: =IF(A25>0,1,"") -> 1 | AQ25: =IF(AN25="","",+AM25/AN25) -> 1 | AR25: =IF(A25="","",VLOOKUP(A25,'Base Sites'!A:B,2,FALSE)) -> Valauto Lomme | AS25: =IF(C25="VW","VOLKSWAGEN",IF(C25="SE","SEAT",IF(C25="NI","NISSAN",IF(C25="HY","HYUNDAI",IF(C25="VU","VUL",IF(C25="sk","SKODA",IF(C25="ltsk","SKODA",IF(C25="CUPRA","CUPRA",IF(C25="AUDI","AUDI",""))))))))) -> HYUNDAI | AU25: =IF(A25="","",VLOOKUP(L25,'Base Vendeurs'!A:B,2,FALSE)) -> Hyundai Lomme | AV25: =+V25+AO25 -> -4215.91 | AW25: =IF(A25="","",+AV25/T25) -> -0.084968823 | AX25: =IF(AV25<0,"OUI","NON") -> OUI | AY25: =+MargesVN[[#This Row],[Total COM]]+MargesVN[[#This Row],[EXT GIE]]+MargesVN[[#This Row],[Forfait immat]] -> 300
A26: 70 | B26: C | C26: HY | D26: 46043 | E26: 46045 | K26: 0 | L26: LEGJA | M26: 5579 | N26: 2105325861 | O26: NLHBN51G0SZ549836 | P26: VERKINDERE CAMILLE | Q26: I20 | R26: 19879.09 | S26: 458.33 | T26: =+R26+S26 -> 20337.42 | U26: 443 | V26: 806.89 | W26: 0 | Y26: =+V26-W26+X26 -> 806.89 | Z26: =(V26+X26)/T26 -> 0.039675141 | AA26: -2021.76 | AB26: 0 | AE26: 0.13 | AF26: 0.13 | AG26: =+Y26*AE26 -> 104.8957 | AI26: =+AG26+AH26 -> 104.8957 | AJ26: Hyundai Finance | AK26: 30 | AL26: 100 | AM26: =IF(AL26>0,100%,0%) -> 1 | AN26: =IF(A26>0,1,"") -> 1 | AQ26: =IF(AN26="","",+AM26/AN26) -> 1 | AR26: =IF(A26="","",VLOOKUP(A26,'Base Sites'!A:B,2,FALSE)) -> Valauto Lomme | AS26: =IF(C26="VW","VOLKSWAGEN",IF(C26="SE","SEAT",IF(C26="NI","NISSAN",IF(C26="HY","HYUNDAI",IF(C26="VU","VUL",IF(C26="sk","SKODA",IF(C26="ltsk","SKODA",IF(C26="CUPRA","CUPRA",IF(C26="AUDI","AUDI",""))))))))) -> HYUNDAI | AU26: =IF(A26="","",VLOOKUP(L26,'Base Vendeurs'!A:B,2,FALSE)) -> Hyundai Lomme | AV26: =+V26+AO26 -> 806.89 | AW26: =IF(A26="","",+AV26/T26) -> 0.039675141 | AX26: =IF(AV26<0,"OUI","NON") -> NON | AY26: =+MargesVN[[#This Row],[Total COM]]+MargesVN[[#This Row],[EXT GIE]]+MargesVN[[#This Row],[Forfait immat]] -> 234.8957
A27: 70 | B27: C | C27: HY | D27: 46114 | E27: 46116 | K27: 0 | L27: LELBO | M27: 5593 | N27: 2105467969 | O27: NLHBN81G7SZ532095 | P27: THIRON MARIE-CAMILLE | Q27: BAYON | R27: 21795.76 | S27: 166.67 | T27: =+R27+S27 -> 21962.43 | U27: 486 | V27: 547.27 | W27: 0 | Y27: =+V27-W27+X27 -> 547.27 | Z27: =(V27+X27)/T27 -> 0.024918463 | AA27: -3569.26 | AB27: 0 | AD27: VN vendu 19990€ au lieu de 21990€ | AF27: 0.13 | AG27: =+Y27*AE27 -> 0 | AH27: 150 | AI27: =+AG27+AH27 -> 150 | AK27: 0 | AM27: =IF(AL27>0,100%,0%) -> 0 | AN27: =IF(A27>0,1,"") -> 1 | AQ27: =IF(AN27="","",+AM27/AN27) -> 0 | AR27: =IF(A27="","",VLOOKUP(A27,'Base Sites'!A:B,2,FALSE)) -> Valauto Lomme | AS27: =IF(C27="VW","VOLKSWAGEN",IF(C27="SE","SEAT",IF(C27="NI","NISSAN",IF(C27="HY","HYUNDAI",IF(C27="VU","VUL",IF(C27="sk","SKODA",IF(C27="ltsk","SKODA",IF(C27="CUPRA","CUPRA",IF(C27="AUDI","AUDI",""))))))))) -> HYUNDAI | AU27: =IF(A27="","",VLOOKUP(L27,'Base Vendeurs'!A:B,2,FALSE)) -> Hyundai Lomme | AV27: =+V27+AO27 -> 547.27 | AW27: =IF(A27="","",+AV27/T27) -> 0.024918463 | AX27: =IF(AV27<0,"OUI","NON") -> NON | AY27: =+MargesVN[[#This Row],[Total COM]]+MargesVN[[#This Row],[EXT GIE]]+MargesVN[[#This Row],[Forfait immat]] -> 150
A28: 70 | B28: C | C28: HY | D28: 46154 | E28: 46157 | L28: LEGCH | M28: 5604 | N28: 2105476163 | O28: NLHBN51G4SZ562234 | P28: COUTEREAU CAMILLE | Q28: I20 | R28: 18712.43 | S28: 166.67 | T28: =+R28+S28 -> 18879.1 | U28: 526 | V28: 1351.98 | W28: -0.01 | X28: -354.08 | Y28: =+V28-W28+X28 -> 997.91 | Z28: =(V28+X28)/T28 -> 0.052857393 | AA28: -2257.26 | AB28: 0 | AE28: 0.12 | AF28: 0.13 | AG28: =+Y28*AE28 -> 119.7492 | AI28: =+AG28+AH28 -> 119.7492 | AJ28: Hyundai Finance | AK28: 0 | AL28: 50 | AM28: =IF(AL28>0,100%,0%) -> 1 | AN28: =IF(A28>0,1,"") -> 1 | AQ28: =IF(AN28="","",+AM28/AN28) -> 1 | AR28: =IF(A28="","",VLOOKUP(A28,'Base Sites'!A:B,2,FALSE)) -> Valauto Lomme | AS28: =IF(C28="VW","VOLKSWAGEN",IF(C28="SE","SEAT",IF(C28="NI","NISSAN",IF(C28="HY","HYUNDAI",IF(C28="VU","VUL",IF(C28="sk","SKODA",IF(C28="ltsk","SKODA",IF(C28="CUPRA","CUPRA",IF(C28="AUDI","AUDI",""))))))))) -> HYUNDAI | AU28: =IF(A28="","",VLOOKUP(L28,'Base Vendeurs'!A:B,2,FALSE)) -> Hyundai Lomme | AV28: =+V28+AO28 -> 1351.98 | AW28: =IF(A28="","",+AV28/T28) -> 0.071612524 | AX28: =IF(AV28<0,"OUI","NON") -> NON | AY28: =+MargesVN[[#This Row],[Total COM]]+MargesVN[[#This Row],[EXT GIE]]+MargesVN[[#This Row],[Forfait immat]] -> 169.7492
A29: 70 | B29: C | C29: HY | D29: 46176 | E29: 46178 | L29: LEGCH | M29: 5606 | N29: 2105476168 | O29: NLHBR81G7SZ491584 | P29: SAWADOGO AURELIEN | Q29: BAYON | R29: 23045.76 | S29: 166.67 | T29: =+R29+S29 -> 23212.43 | U29: 548 | V29: -590.08 | W29: 0 | Y29: =+V29-W29+X29 -> -590.08 | Z29: =(V29+X29)/T29 -> -0.025420863 | AA29: -3679.26 | AB29: 0 | AD29: marge négative // 0 forfait demandé | AF29: 0.13 | AG29: =+Y29*AE29 -> 0 | AI29: =+AG29+AH29 -> 0 | AJ29: Hyundai Finance | AK29: 0 | AM29: =IF(AL29>0,100%,0%) -> 0 | AN29: =IF(A29>0,1,"") -> 1 | AQ29: =IF(AN29="","",+AM29/AN29) -> 0 | AR29: =IF(A29="","",VLOOKUP(A29,'Base Sites'!A:B,2,FALSE)) -> Valauto Lomme | AS29: =IF(C29="VW","VOLKSWAGEN",IF(C29="SE","SEAT",IF(C29="NI","NISSAN",IF(C29="HY","HYUNDAI",IF(C29="VU","VUL",IF(C29="sk","SKODA",IF(C29="ltsk","SKODA",IF(C29="CUPRA","CUPRA",IF(C29="AUDI","AUDI",""))))))))) -> HYUNDAI | AU29: =IF(A29="","",VLOOKUP(L29,'Base Vendeurs'!A:B,2,FALSE)) -> Hyundai Lomme | AV29: =+V29+AO29 -> -590.08 | AW29: =IF(A29="","",+AV29/T29) -> -0.025420863 | AX29: =IF(AV29<0,"OUI","NON") -> OUI | AY29: =+MargesVN[[#This Row],[Total COM]]+MargesVN[[#This Row],[EXT GIE]]+MargesVN[[#This Row],[Forfait immat]] -> 0
A30: 70 | B30: C | C30: HY | D30: 46198 | E30: 46178 | L30: LEGCH | M30: 5622 | N30: 2105493478 | O30: NLHDR51C1SZ333228 | P30: PARMENTIER MARIE-JEANNE | Q30: I10 | R30: 16670.76 | S30: 416.67 | T30: =+R30+S30 -> 17087.43 | U30: 553 | V30: 968.3 | W30: 0 | Y30: =+V30-W30+X30 -> 968.3 | Z30: =(V30+X30)/T30 -> 0.056667386 | AA30: -1830.26 | AB30: 0 | AE30: 0.13 | AF30: 0.13 | AG30: =+Y30*AE30 -> 125.879 | AI30: =+AG30+AH30 -> 125.879 | AJ30: Hyundai Finance | AK30: 30 | AL30: 100 | AM30: =IF(AL30>0,100%,0%) -> 1 | AN30: =IF(A30>0,1,"") -> 1 | AQ30: =IF(AN30="","",+AM30/AN30) -> 1 | AR30: =IF(A30="","",VLOOKUP(A30,'Base Sites'!A:B,2,FALSE)) -> Valauto Lomme | AS30: =IF(C30="VW","VOLKSWAGEN",IF(C30="SE","SEAT",IF(C30="NI","NISSAN",IF(C30="HY","HYUNDAI",IF(C30="VU","VUL",IF(C30="sk","SKODA",IF(C30="ltsk","SKODA",IF(C30="CUPRA","CUPRA",IF(C30="AUDI","AUDI",""))))))))) -> HYUNDAI | AU30: =IF(A30="","",VLOOKUP(L30,'Base Vendeurs'!A:B,2,FALSE)) -> Hyundai Lomme | AV30: =+V30+AO30 -> 968.3 | AW30: =IF(A30="","",+AV30/T30) -> 0.056667386 | AX30: =IF(AV30<0,"OUI","NON") -> NON | AY30: =+MargesVN[[#This Row],[Total COM]]+MargesVN[[#This Row],[EXT GIE]]+MargesVN[[#This Row],[Forfait immat]] -> 255.879
A31: 70 | B31: C | C31: HY | D31: 46192 | E31: 46192 | K31: 0 | L31: LEGJA | M31: 5676 | N31: 2105579562 | O31: NLHBR81G8SZ600781 | P31: FLAMENT AURELIEN | Q31: BAYON | R31: 23420.76 | S31: 0 | T31: =+R31+S31 -> 23420.76 | U31: 478 | V31: 297.1 | W31: 0 | Y31: =+V31-W31+X31 -> 297.1 | Z31: =(V31+X31)/T31 -> 0.012685327 | AA31: -1389.76 | AB31: -2292 | AD31: 0 comm demandée // Challenge VD | AF31: 0.13 | AG31: =+Y31*AE31 -> 0 | AH31: 300 | AI31: =+AG31+AH31 -> 300 | AJ31: Hyundai Finance | AK31: 0 | AL31: 100 | AM31: =IF(AL31>0,100%,0%) -> 1 | AN31: =IF(A31>0,1,"") -> 1 | AQ31: =IF(AN31="","",+AM31/AN31) -> 1 | AR31: =IF(A31="","",VLOOKUP(A31,'Base Sites'!A:B,2,FALSE)) -> Valauto Lomme | AS31: =IF(C31="VW","VOLKSWAGEN",IF(C31="SE","SEAT",IF(C31="NI","NISSAN",IF(C31="HY","HYUNDAI",IF(C31="VU","VUL",IF(C31="sk","SKODA",IF(C31="ltsk","SKODA",IF(C31="CUPRA","CUPRA",IF(C31="AUDI","AUDI",""))))))))) -> HYUNDAI | AU31: =IF(A31="","",VLOOKUP(L31,'Base Vendeurs'!A:B,2,FALSE)) -> Hyundai Lomme | AV31: =+V31+AO31 -> 297.1 | AW31: =IF(A31="","",+AV31/T31) -> 0.012685327 | AX31: =IF(AV31<0,"OUI","NON") -> NON | AY31: =+MargesVN[[#This Row],[Total COM]]+MargesVN[[#This Row],[EXT GIE]]+MargesVN[[#This Row],[Forfait immat]] -> 400
A32: 70 | B32: C | C32: HY | D32: 46072 | E32: 46074 | K32: 0 | L32: LEGJA | M32: 5682 | N32: 2105499998 | O32: KMHP58119SU095400 | P32: GROUX OLIVIER | Q32: SANTA FE | R32: 49000.48 | S32: 833.33 | T32: =+R32+S32 -> 49833.81 | U32: 358 | V32: 8945.1 | W32: -0.01 | X32: -7166 | Y32: =+V32-W32+X32 -> 1779.11 | Z32: =(V32+X32)/T32 -> 0.035700662 | AA32: -10334.54 | AB32: 0 | AD32: marge négative // Challenge vieux stock | AF32: 0.13 | AG32: =+Y32*AE32 -> 0 | AH32: 300 | AI32: =+AG32+AH32 -> 300 | AK32: 0 | AL32: 100 | AM32: =IF(AL32>0,100%,0%) -> 1 | AN32: =IF(A32>0,1,"") -> 1 | AQ32: =IF(AN32="","",+AM32/AN32) -> 1 | AR32: =IF(A32="","",VLOOKUP(A32,'Base Sites'!A:B,2,FALSE)) -> Valauto Lomme | AS32: =IF(C32="VW","VOLKSWAGEN",IF(C32="SE","SEAT",IF(C32="NI","NISSAN",IF(C32="HY","HYUNDAI",IF(C32="VU","VUL",IF(C32="sk","SKODA",IF(C32="ltsk","SKODA",IF(C32="CUPRA","CUPRA",IF(C32="AUDI","AUDI",""))))))))) -> HYUNDAI | AU32: =IF(A32="","",VLOOKUP(L32,'Base Vendeurs'!A:B,2,FALSE)) -> Hyundai Lomme | AV32: =+V32+AO32 -> 8945.1 | AW32: =IF(A32="","",+AV32/T32) -> 0.17949862 | AX32: =IF(AV32<0,"OUI","NON") -> NON | AY32: =+MargesVN[[#This Row],[Total COM]]+MargesVN[[#This Row],[EXT GIE]]+MargesVN[[#This Row],[Forfait immat]] -> 400
A33: 70 | B33: C | C33: HY | D33: 46028 | E33: 46028 | K33: 0 | L33: LEGCH | M33: 5702 | N33: 2105621085 | O33: TMAJB811XSJ333148 | P33: GUNST PHILIPPE | Q33: TUCSON | R33: 40792.14 | S33: 541.67 | T33: =+R33+S33 -> 41333.81 | U33: 288 | V33: 2630.27 | W33: 0 | Y33: =+V33-W33+X33 -> 2630.27 | Z33: =(V33+X33)/T33 -> 0.063634831 | AA33: -4131.54 | AB33: 0 | AE33: 0.13 | AF33: 0.13 | AG33: =+Y33*AE33 -> 341.9351 | AI33: =+AG33+AH33 -> 341.9351 | AJ33: Hyundai Finance | AK33: 0 | AL33: 50 | AM33: =IF(AL33>0,100%,0%) -> 1 | AN33: =IF(A33>0,1,"") -> 1 | AQ33: =IF(AN33="","",+AM33/AN33) -> 1 | AR33: =IF(A33="","",VLOOKUP(A33,'Base Sites'!A:B,2,FALSE)) -> Valauto Lomme | AS33: =IF(C33="VW","VOLKSWAGEN",IF(C33="SE","SEAT",IF(C33="NI","NISSAN",IF(C33="HY","HYUNDAI",IF(C33="VU","VUL",IF(C33="sk","SKODA",IF(C33="ltsk","SKODA",IF(C33="CUPRA","CUPRA",IF(C33="AUDI","AUDI",""))))))))) -> HYUNDAI | AU33: =IF(A33="","",VLOOKUP(L33,'Base Vendeurs'!A:B,2,FALSE)) -> Hyundai Lomme | AV33: =+V33+AO33 -> 2630.27 | AW33: =IF(A33="","",+AV33/T33) -> 0.063634831 | AX33: =IF(AV33<0,"OUI","NON") -> NON | AY33: =+MargesVN[[#This Row],[Total COM]]+MargesVN[[#This Row],[EXT GIE]]+MargesVN[[#This Row],[Forfait immat]] -> 391.9351
A34: 70 | B34: C | C34: HY | D34: 46065 | E34: 46067 | K34: 0 | L34: LELBO | M34: 5774 | N34: 2105737341 | O34: KMHB15124TW037827 | P34: NOLTE ALEXANDRE | Q34: INSTER | R34: 20379.09 | S34: 250 | T34: =+R34+S34 -> 20629.09 | U34: 227 | V34: 1706.88 | W34: 0 | Y34: =+V34-W34+X34 -> 1706.88 | Z34: =(V34+X34)/T34 -> 0.08274141 | AA34: -2070.26 | AB34: 0 | AE34: 0.13 | AF34: 0.13 | AG34: =+Y34*AE34 -> 221.8944 | AI34: =+AG34+AH34 -> 221.8944 | AJ34: Hyundai Finance | AK34: 0 | AL34: 0 | AM34: =IF(AL34>0,100%,0%) -> 1 | AN34: =IF(A34>0,1,"") -> 1 | AQ34: =IF(AN34="","",+AM34/AN34) -> 1 | AR34: =IF(A34="","",VLOOKUP(A34,'Base Sites'!A:B,2,FALSE)) -> Valauto Lomme | AS34: =IF(C34="VW","VOLKSWAGEN",IF(C34="SE","SEAT",IF(C34="NI","NISSAN",IF(C34="HY","HYUNDAI",IF(C34="VU","VUL",IF(C34="sk","SKODA",IF(C34="ltsk","SKODA",IF(C34="CUPRA","CUPRA",IF(C34="AUDI","AUDI",""))))))))) -> HYUNDAI | AU34: =IF(A34="","",VLOOKUP(L34,'Base Vendeurs'!A:B,2,FALSE)) -> Hyundai Lomme | AV34: =+V34+AO34 -> 1706.88 | AW34: =IF(A34="","",+AV34/T34) -> 0.08274141 | AX34: =IF(AV34<0,"OUI","NON") -> NON | AY34: =+MargesVN[[#This Row],[Total COM]]+MargesVN[[#This Row],[EXT GIE]]+MargesVN[[#This Row],[Forfait immat]] -> 221.8944
A35: 70 | B35: C | C35: HY | D35: 46059 | E35: 46053 | K35: 0 | L35: LELBO | M35: 5776 | N35: 2105723724 | O35: TMAH881B1SJ064706 | P35: BELBACHIR ANAIS | Q35: KONA | R35: 30254.09 | S35: 541.67 | T35: =+R35+S35 -> 30795.76 | U35: 213 | V35: 1170.18 | W35: 0 | Y35: =+V35-W35+X35 -> 1170.18 | Z35: =(V35+X35)/T35 -> 0.037998088 | AA35: -3180.26 | AB35: 0 | AE35: 0.13 | AF35: 0.13 | AG35: =+Y35*AE35 -> 152.1234 | AI35: =+AG35+AH35 -> 152.1234 | AJ35: Hyundai Finance | AK35: 0 | AL35: 0 | AM35: =IF(AL35>0,100%,0%) -> 1 | AN35: =IF(A35>0,1,"") -> 1 | AQ35: =IF(AN35="","",+AM35/AN35) -> 1 | AR35: =IF(A35="","",VLOOKUP(A35,'Base Sites'!A:B,2,FALSE)) -> Valauto Lomme | AS35: =IF(C35="VW","VOLKSWAGEN",IF(C35="SE","SEAT",IF(C35="NI","NISSAN",IF(C35="HY","HYUNDAI",IF(C35="VU","VUL",IF(C35="sk","SKODA",IF(C35="ltsk","SKODA",IF(C35="CUPRA","CUPRA",IF(C35="AUDI","AUDI",""))))))))) -> HYUNDAI | AU35: =IF(A35="","",VLOOKUP(L35,'Base Vendeurs'!A:B,2,FALSE)) -> Hyundai Lomme | AV35: =+V35+AO35 -> 1170.18 | AW35: =IF(A35="","",+AV35/T35) -> 0.037998088 | AX35: =IF(AV35<0,"OUI","NON") -> NON | AY35: =+MargesVN[[#This Row],[Total COM]]+MargesVN[[#This Row],[EXT GIE]]+MargesVN[[#This Row],[Forfait immat]] -> 152.1234
A36: 70 | B36: C | C36: HY | D36: 46059 | E36: 46044 | L36: LEGCH | M36: 5787 | N36: 2105758814 | O36: KMHHE8115SU132110 | P36: POTIER MARIE-JOSE | Q36: KONA | R36: 33004.09 | S36: 833.34 | T36: =+R36+S36 -> 33837.43 | U36: 190 | V36: 2830.09 | W36: 0 | Y36: =+V36-W36+X36 -> 2830.09 | Z36: =(V36+X36)/T36 -> 0.083637853 | AA36: -4014.76 | AB36: 0 | AE36: 0.13 | AF36: 0.13 | AG36: =+Y36*AE36 -> 367.9117 | AI36: =+AG36+AH36 -> 367.9117 | AJ36: Hyundai Finance | AK36: 0 | AL36: 100 | AM36: =IF(AL36>0,100%,0%) -> 1 | AN36: =IF(A36>0,1,"") -> 1 | AQ36: =IF(AN36="","",+AM36/AN36) -> 1 | AR36: =IF(A36="","",VLOOKUP(A36,'Base Sites'!A:B,2,FALSE)) -> Valauto Lomme | AS36: =IF(C36="VW","VOLKSWAGEN",IF(C36="SE","SEAT",IF(C36="NI","NISSAN",IF(C36="HY","HYUNDAI",IF(C36="VU","VUL",IF(C36="sk","SKODA",IF(C36="ltsk","SKODA",IF(C36="CUPRA","CUPRA",IF(C36="AUDI","AUDI",""))))))))) -> HYUNDAI | AU36: =IF(A36="","",VLOOKUP(L36,'Base Vendeurs'!A:B,2,FALSE)) -> Hyundai Lomme | AV36: =+V36+AO36 -> 2830.09 | AW36: =IF(A36="","",+AV36/T36) -> 0.083637853 | AX36: =IF(AV36<0,"OUI","NON") -> NON | AY36: =+MargesVN[[#This Row],[Total COM]]+MargesVN[[#This Row],[EXT GIE]]+MargesVN[[#This Row],[Forfait immat]] -> 467.9117
A37: 70 | B37: C | C37: HY | D37: 46059 | E37: 46060 | K37: 0 | L37: LETLE | M37: 5791 | N37: 2105758816 | O37: NLHBN51G5SZ631710 | P37: PLATTEAU THIERRY | Q37: I20 | R37: 20045.76 | S37: 458.33 | T37: =+R37+S37 -> 20504.09 | U37: 189 | V37: 1619.64 | W37: 0 | Y37: =+V37-W37+X37 -> 1619.64 | Z37: =(V37+X37)/T37 -> 0.07899107 | AA37: -792 | AB37: 0 | AE37: 0.13 | AF37: 0.13 | AG37: =+Y37*AE37 -> 210.5532 | AI37: =+AG37+AH37 -> 210.5532 | AJ37: Hyundai Finance | AK37: 0 | AL37: 50 | AM37: =IF(AL37>0,100%,0%) -> 1 | AN37: =IF(A37>0,1,"") -> 1 | AQ37: =IF(AN37="","",+AM37/AN37) -> 1 | AR37: =IF(A37="","",VLOOKUP(A37,'Base Sites'!A:B,2,FALSE)) -> Valauto Lomme | AS37: =IF(C37="VW","VOLKSWAGEN",IF(C37="SE","SEAT",IF(C37="NI","NISSAN",IF(C37="HY","HYUNDAI",IF(C37="VU","VUL",IF(C37="sk","SKODA",IF(C37="ltsk","SKODA",IF(C37="CUPRA","CUPRA",IF(C37="AUDI","AUDI",""))))))))) -> HYUNDAI | AU37: =IF(A37="","",VLOOKUP(L37,'Base Vendeurs'!A:B,2,FALSE)) -> Hyundai Lomme | AV37: =+V37+AO37 -> 1619.64 | AW37: =IF(A37="","",+AV37/T37) -> 0.07899107 | AX37: =IF(AV37<0,"OUI","NON") -> NON | AY37: =+MargesVN[[#This Row],[Total COM]]+MargesVN[[#This Row],[EXT GIE]]+MargesVN[[#This Row],[Forfait immat]] -> 260.5532
A38: 70 | B38: C | C38: HY | D38: 46191 | E38: 46192 | K38: 0 | L38: LEGCH | M38: 5793 | N38: 2105765574 | O38: KMHMY8158TA006285 | P38: BABOL SERVICES | Q38: IONIQ 9 | R38: 71750.48 | S38: 0 | T38: =+R38+S38 -> 71750.48 | U38: 316 | V38: 1864.83 | W38: 0 | Y38: =+V38-W38+X38 -> 1864.83 | Z38: =(V38+X38)/T38 -> 0.025990488 | AA38: -4304.54 | AB38: -15209.39 | AE38: 0.13 | AF38: 0.13 | AG38: =+Y38*AE38 -> 242.4279 | AI38: =+AG38+AH38 -> 242.4279 | AK38: 0 | AL38: 50 | AM38: =IF(AL38>0,100%,0%) -> 1 | AN38: =IF(A38>0,1,"") -> 1 | AQ38: =IF(AN38="","",+AM38/AN38) -> 1 | AR38: =IF(A38="","",VLOOKUP(A38,'Base Sites'!A:B,2,FALSE)) -> Valauto Lomme | AS38: =IF(C38="VW","VOLKSWAGEN",IF(C38="SE","SEAT",IF(C38="NI","NISSAN",IF(C38="HY","HYUNDAI",IF(C38="VU","VUL",IF(C38="sk","SKODA",IF(C38="ltsk","SKODA",IF(C38="CUPRA","CUPRA",IF(C38="AUDI","AUDI",""))))))))) -> HYUNDAI | AU38: =IF(A38="","",VLOOKUP(L38,'Base Vendeurs'!A:B,2,FALSE)) -> Hyundai Lomme | AV38: =+V38+AO38 -> 1864.83 | AW38: =IF(A38="","",+AV38/T38) -> 0.025990488 | AX38: =IF(AV38<0,"OUI","NON") -> NON | AY38: =+MargesVN[[#This Row],[Total COM]]+MargesVN[[#This Row],[EXT GIE]]+MargesVN[[#This Row],[Forfait immat]] -> 292.4279
A39: 70 | B39: C | C39: HY | D39: 46154 | E39: 46157 | K39: 0 | L39: LEGJA | M39: 5804 | N39: 2105787175 | O39: TMAJE8114SJ415030 | P39: VERREYDT JEREMY | Q39: TUCSON | R39: 39958.81 | S39: 541.67 | T39: =+R39+S39 -> 40500.48 | U39: 256 | V39: 2173.61 | W39: 0 | Y39: =+V39-W39+X39 -> 2173.61 | Z39: =(V39+X39)/T39 -> 0.053668747 | AA39: -5330.54 | AB39: 0 | AE39: 0.12 | AF39: 0.13 | AG39: =+Y39*AE39 -> 260.8332 | AI39: =+AG39+AH39 -> 260.8332 | AK39: 0 | AL39: 50 | AM39: =IF(AL39>0,100%,0%) -> 1 | AN39: =IF(A39>0,1,"") -> 1 | AQ39: =IF(AN39="","",+AM39/AN39) -> 1 | AR39: =IF(A39="","",VLOOKUP(A39,'Base Sites'!A:B,2,FALSE)) -> Valauto Lomme | AS39: =IF(C39="VW","VOLKSWAGEN",IF(C39="SE","SEAT",IF(C39="NI","NISSAN",IF(C39="HY","HYUNDAI",IF(C39="VU","VUL",IF(C39="sk","SKODA",IF(C39="ltsk","SKODA",IF(C39="CUPRA","CUPRA",IF(C39="AUDI","AUDI",""))))))))) -> HYUNDAI | AU39: =IF(A39="","",VLOOKUP(L39,'Base Vendeurs'!A:B,2,FALSE)) -> Hyundai Lomme | AV39: =+V39+AO39 -> 2173.61 | AW39: =IF(A39="","",+AV39/T39) -> 0.053668747 | AX39: =IF(AV39<0,"OUI","NON") -> NON | AY39: =+MargesVN[[#This Row],[Total COM]]+MargesVN[[#This Row],[EXT GIE]]+MargesVN[[#This Row],[Forfait immat]] -> 310.8332
A40: 70 | B40: C | C40: HY | D40: 46092 | E40: 46094 | L40: LEGJA | M40: 5811 | N40: 2105787158 | O40: KMHHB8111TU166507 | P40: WILCZAK EDOUARD | Q40: KONA | R40: 35504.09 | S40: 458.33 | T40: =+R40+S40 -> 35962.42 | U40: 191 | V40: 1082.31 | W40: 0 | Y40: =+V40-W40+X40 -> 1082.31 | Z40: =(V40+X40)/T40 -> 0.030095583 | AA40: -3784.26 | AB40: 0 | AE40: 0.13 | AF40: 0.13 | AG40: =+Y40*AE40 -> 140.7003 | AI40: =+AG40+AH40 -> 140.7003 | AJ40: Hyundai Finance | AL40: 100 | AM40: =IF(AL40>0,100%,0%) -> 1 | AN40: =IF(A40>0,1,"") -> 1 | AQ40: =IF(AN40="","",+AM40/AN40) -> 1 | AR40: =IF(A40="","",VLOOKUP(A40,'Base Sites'!A:B,2,FALSE)) -> Valauto Lomme | AS40: =IF(C40="VW","VOLKSWAGEN",IF(C40="SE","SEAT",IF(C40="NI","NISSAN",IF(C40="HY","HYUNDAI",IF(C40="VU","VUL",IF(C40="sk","SKODA",IF(C40="ltsk","SKODA",IF(C40="CUPRA","CUPRA",IF(C40="AUDI","AUDI",""))))))))) -> HYUNDAI | AU40: =IF(A40="","",VLOOKUP(L40,'Base Vendeurs'!A:B,2,FALSE)) -> Hyundai Lomme | AV40: =+V40+AO40 -> 1082.31 | AW40: =IF(A40="","",+AV40/T40) -> 0.030095583 | AX40: =IF(AV40<0,"OUI","NON") -> NON | AY40: =+MargesVN[[#This Row],[Total COM]]+MargesVN[[#This Row],[EXT GIE]]+MargesVN[[#This Row],[Forfait immat]] -> 240.7003
...

Sheet VérifCARBASE
A1: Date de Facturation | B1: (Tous)
A3: Nombre de N° VN | B3: Étiquettes de colonnes | M3: Ecart | N3: MAJ FB 28/07 au 30/06/2026
A4: Étiquettes de lignes | B4: HY | C4: SE | D4: SK | E4: VU | F4: VW | G4: CUPRA | H4: AUDI | I4: Total général
A5: 10 | C5: 32 | D5: 135 | F5: 325 | G5: 61 | I5: 553 | L5: =627-5-69 -> 553 | M5: =I5-L5 -> 0 | N5: OK
A6: 20 | E6: 90 | I6: 90 | L6: =92-4 -> 88 | M6: =I6-L6 -> 2 | N6: VN514231 et 519509 (valauto Rent) classés en groupe en compta
A7: 30 | D7: 427 | F7: 363 | I7: 790 | L7: =825-38 -> 787 | M7: =I7-L7 -> 3 | N7: VN548334, 524807 et 519691 (valauto Rent) classés en groupe en compta
A8: 60 | F8: 188 | I8: 188 | L8: =232-1-43 -> 188 | M8: =I8-L8 -> 0 | N8: OK
A9: 70 | B9: 150 | I9: 150 | L9: 150 | M9: =I9-L9 -> 0 | N9: OK
A10: 15 | E10: 40 | F10: 238 | H10: 98 | I10: 376 | L10: =426-2-50 -> 374 | M10: =I10-L10 -> 2 | N10: VN20062 et 519546 (valauto Rent) classés en groupe en compta
A11: 25 | F11: 45 | I11: 45 | L11: =64-1-20 -> 43 | M11: =I11-L11 -> 2 | N11: VN519536 et 519545 (valauto Rent) classés en groupe en compta
A12: 35 | C12: 17 | D12: 47 | F12: 81 | G12: 5 | I12: 150 | L12: =187-40 -> 147 | M12: =I12-L12 -> 3 | N12: VN517836, 537924 et 519515 (valauto Rent) classés en groupe en compta
A13: 45 | C13: 2 | D13: 17 | E13: 9 | F13: 150 | G13: 15 | I13: 193 | L13: =225-32 -> 193 | M13: =I13-L13 -> 0 | N13: OK
A14: Total général | B14: 150 | C14: 51 | D14: 626 | E14: 139 | F14: 1390 | G14: 81 | H14: 98 | I14: 2535

Sheet CLE REPARTITION CELL ENT
A1: Tableau - Clef de répartition pour facturation MAD Cellule Entreprise
B11: Étiquettes de colonnes
B12: AUDI | D12: CUPRA | F12: HY | H12: SE | J12: SK | L12: VU | N12: VW | P12: Total Nbre VN | Q12: Total Somme de Marge nette recalculée
A13: Étiquettes de lignes | B13: Nbre VN | C13: Somme de Marge nette recalculée | D13: Nbre VN | E13: Somme de Marge nette recalculée | F13: Nbre VN | G13: Somme de Marge nette recalculée | H13: Nbre VN | I13: Somme de Marge nette recalculée | J13: Nbre VN | K13: Somme de Marge nette recalculée | L13: Nbre VN | M13: Somme de Marge nette recalculée | N13: Nbre VN | O13: Somme de Marge nette recalculée
A14: 10 | D14: 22 | E14: 23053.65 | H14: 15 | I14: 9114.93 | J14: 22 | K14: 22981.49 | N14: 2 | O14: 2402.85 | P14: 61 | Q14: 57552.92
A15: 15 | B15: 31 | C15: 53342.2 | L15: 7 | M15: 12224.16 | N15: 117 | O15: 112271.07 | P15: 155 | Q15: 177837.43
A16: 20 | L16: 36 | M16: 33172.24 | P16: 36 | Q16: 33172.24
A17: 25 | N17: 5 | O17: 4417.88 | P17: 5 | Q17: 4417.88
A18: 30 | J18: 271 | K18: 210056.36 | N18: 189 | O18: 197182.52 | P18: 460 | Q18: 407238.88
A19: 35 | D19: 1 | E19: 1246.83 | H19: 3 | I19: 1870.62 | J19: 16 | K19: 14431.65 | N19: 9 | O19: 5948.09 | P19: 29 | Q19: 23497.19
A20: 45 | D20: 1 | E20: 932.2 | J20: 3 | K20: 3511.21 | L20: 5 | M20: 3629.39 | N20: 13 | O20: 12756.91 | P20: 22 | Q20: 20829.71
A21: 60 | N21: 61 | O21: 31053.12 | P21: 61 | Q21: 31053.12
A22: 70 | F22: 15 | G22: 7605.84 | P22: 15 | Q22: 7605.84
A23: Total général | B23: 31 | C23: 53342.2 | D23: 24 | E23: 25232.68 | F23: 15 | G23: 7605.84 | H23: 18 | I23: 10985.55 | J23: 312 | K23: 250980.71 | L23: 48 | M23: 49025.79 | N23: 396 | O23: 366032.44 | P23: 844 | Q23: 763205.21

Sheet Détails1
A1: Détails pou for Somme de Marge nette recalculée - Marque: VU, CLIENT: WULLENS YOANN, Modèle livré: ID BUZZ, Date de Livraison: 1/3/2022, Marque4 : (+)
A3: Site | B3: Etat | C3: Marque | D3: Date de Facturation | E3: Date de Livraison | F3: Manque Marge | G3: PB Marge | H3: Justif ? | I3: Solde Client | J3: Validé DF | K3: Solde client2 | L3: Vendeur | M3: N° VN | N3: N° CDE | O3: Châssis | P3: CLIENT | Q3: Modèle livré | R3: Prix de Vte | S3: Options | T3: Total | U3: Jours de Stock | V3: Marge nette | W3: Marge s/transport | X3: déduction diverse | Y3: Marge restante | Z3: % PV | AA3: OP Clos | AB3: OP Ouverts | AC3: OP non visible | AD3: libellé OP non visible | AE3: TX COM | AF3: TX COM Opticar | AG3: Commission de Base | AH3: Prime opération | AI3: Total COM | AJ3: Sté de Financement | AK3: EXT GIE | AL3: Forfait immat | AM3: nbre de forfait | AN3: nbre de livraison | AO3: OP "+ / -" | AP3: date | AQ3: % forfait | AR3: AU | AS3: Marque4 | AT3: non utilisé | AU3: Equipe | AV3: Marge nette recalculée | AW3: % PV5 | AX3: Marge négative | AY3: TOTAL COM VENDEUR
A4: 30 | B4: C | C4: VU | D4: 45847 | E4: 45849 | K4: 0 | L4: VRGWI | M4: 32702 | N4: 9500 | O4: WV2ZZZEB4PH005520 | P4: WULLENS YOANN | Q4: ID BUZZ | R4: 48861.47 | S4: 0 | T4: 48861.47 | U4: 145 | V4: 1406.8 | Y4: 1406.8 | Z4: 0.028791602 | AA4: 0 | AB4: 0 | AD4: 0 comm demandé // Forfait // PDV hors CG 41104€ au lieu de 41119€ | AF4: 0.12 | AG4: 0 | AH4: 200 | AI4: 200 | AL4: 20 | AM4: 1 | AN4: 1 | AO4: -21792 | AP4: 45869 | AQ4: 1 | AR4: Valauto Lambersart VW | AU4: Valauto PRO NORD | AV4: -20385.2 | AW4: -0.41720399 | AX4: NON | AY4: 220

Sheet CALCUL RETRO COM
